<?xml version="1.0" encoding="utf-8"?>
<!-- This URDF was automatically created by SolidWorks to URDF Exporter! Originally created by Stephen Brawner (brawner@gmail.com) 
     Commit Version: 1.6.0-1-g15f4949  Build Version: 1.6.7594.29634
     For more information, please see http://wiki.ros.org/sw_urdf_exporter -->
<robot
  name="real_leg_crab2.SLDASM">
  <link
    name="base_link">
    <inertial>
      <origin
        xyz="0.000231589537283588 -0.0130873647004375 -0.0602688286688337"
        rpy="0 0 0" />
      <mass
        value="0.141709434717048" />
      <inertia
        ixx="6.70618311809055E-05"
        ixy="-9.43108317164093E-11"
        ixz="-5.96477348082914E-09"
        iyy="0.000100227113680632"
        iyz="-7.59922194483234E-07"
        izz="5.21785884808558E-05" />
    </inertial>
    <visual>
      <origin
        xyz="0 0 0"
        rpy="0 0 0" />
      <geometry>
        <mesh
          filename="package://real_leg_crab2.SLDASM/meshes/base_link.STL" />
      </geometry>
      <material
        name="">
        <color
          rgba="0.901960784313726 0.874509803921569 0.423529411764706 1" />
      </material>
    </visual>
    <collision>
      <origin
        xyz="0 0 0"
        rpy="0 0 0" />
      <geometry>
        <mesh
          filename="package://real_leg_crab2.SLDASM/meshes/base_link.STL" />
      </geometry>
    </collision>
  </link>
  <link
    name="Link1">
    <inertial>
      <origin
        xyz="0.0200493213690158 0.000674476329405184 0.0651048337427442"
        rpy="0 0 0" />
      <mass
        value="0.0588446880302928" />
      <inertia
        ixx="1.15054825421484E-05"
        ixy="-1.61043885093409E-09"
        ixz="-1.03583135954881E-07"
        iyy="1.42049410424841E-05"
        iyz="-7.79370564583681E-08"
        izz="9.27872701679208E-06" />
    </inertial>
    <visual>
      <origin
        xyz="0 0 0"
        rpy="0 0 0" />
      <geometry>
        <mesh
          filename="package://real_leg_crab2.SLDASM/meshes/Link1.STL" />
      </geometry>
      <material
        name="">
        <color
          rgba="0.792156862745098 0.819607843137255 0.933333333333333 1" />
      </material>
    </visual>
    <collision>
      <origin
        xyz="0 0 0"
        rpy="0 0 0" />
      <geometry>
        <mesh
          filename="package://real_leg_crab2.SLDASM/meshes/Link1.STL" />
      </geometry>
    </collision>
  </link>
  <joint
    name="Joint1"
    type="continuous">
    <origin
      xyz="-0.0189684104627767 -0.012198467902848 8.12184844443536E-05"
      rpy="0 0 0" />
    <parent
      link="base_link" />
    <child
      link="Link1" />
    <axis
      xyz="-1 0 0" />
  </joint>
  <link
    name="Link2">
    <inertial>
      <origin
        xyz="0.0195000237645684 -0.040268015354189 0.0030814844829578"
        rpy="0 0 0" />
      <mass
        value="0.0298822564995821" />
      <inertia
        ixx="1.0955639360336E-05"
        ixy="-2.49672665726687E-11"
        ixz="2.09219135445875E-11"
        iyy="4.15124525137848E-06"
        iyz="1.00791174776623E-06"
        izz="1.32188513983384E-05" />
    </inertial>
    <visual>
      <origin
        xyz="0 0 0"
        rpy="0 0 0" />
      <geometry>
        <mesh
          filename="package://real_leg_crab2.SLDASM/meshes/Link2.STL" />
      </geometry>
      <material
        name="">
        <color
          rgba="0.792156862745098 0.819607843137255 0.933333333333333 1" />
      </material>
    </visual>
    <collision>
      <origin
        xyz="0 0 0"
        rpy="0 0 0" />
      <geometry>
        <mesh
          filename="package://real_leg_crab2.SLDASM/meshes/Link2.STL" />
      </geometry>
    </collision>
  </link>
  <joint
    name="Joint2"
    type="continuous">
    <origin
      xyz="0.000200000000000016 0.00094634532761368 0.092645791028598"
      rpy="0 0 0" />
    <parent
      link="Link1" />
    <child
      link="Link2" />
    <axis
      xyz="-1 0 0" />
  </joint>
  <link
    name="Link_3">
    <inertial>
      <origin
        xyz="0.019243094861785 0.000737491939090743 -0.0515421415644358"
        rpy="0 0 0" />
      <mass
        value="0.0588446880234572" />
      <inertia
        ixx="1.15054825453095E-05"
        ixy="-1.66521000492253E-09"
        ixz="-1.03582270693049E-07"
        iyy="1.42049426490819E-05"
        iyz="-7.78862749134244E-08"
        izz="9.27872541278569E-06" />
    </inertial>
    <visual>
      <origin
        xyz="0 0 0"
        rpy="0 0 0" />
      <geometry>
        <mesh
          filename="package://real_leg_crab2.SLDASM/meshes/Link_3.STL" />
      </geometry>
      <material
        name="">
        <color
          rgba="0.792156862745098 0.819607843137255 0.933333333333333 1" />
      </material>
    </visual>
    <collision>
      <origin
        xyz="0 0 0"
        rpy="0 0 0" />
      <geometry>
        <mesh
          filename="package://real_leg_crab2.SLDASM/meshes/Link_3.STL" />
      </geometry>
    </collision>
  </link>
  <joint
    name="Joint_3"
    type="continuous">
    <origin
      xyz="-0.0195684104627766 -0.0162479818305903 -0.134271960935708"
      rpy="0 0 0" />
    <parent
      link="base_link" />
    <child
      link="Link_3" />
    <axis
      xyz="1 0 0" />
  </joint>
  <link
    name="Link_4">
    <inertial>
      <origin
        xyz="0.019499976259397 -0.0375767316121917 -0.0024364588666686"
        rpy="0 0 0" />
      <mass
        value="0.0298822577380348" />
      <inertia
        ixx="1.0955618630757E-05"
        ixy="2.50137054766782E-11"
        ixz="2.05945482031854E-11"
        iyy="4.11856125869196E-06"
        iyz="-8.47614813831271E-07"
        izz="1.32515148094256E-05" />
    </inertial>
    <visual>
      <origin
        xyz="0 0 0"
        rpy="0 0 0" />
      <geometry>
        <mesh
          filename="package://real_leg_crab2.SLDASM/meshes/Link_4.STL" />
      </geometry>
      <material
        name="">
        <color
          rgba="0.792156862745098 0.819607843137255 0.933333333333333 1" />
      </material>
    </visual>
    <collision>
      <origin
        xyz="0 0 0"
        rpy="0 0 0" />
      <geometry>
        <mesh
          filename="package://real_leg_crab2.SLDASM/meshes/Link_4.STL" />
      </geometry>
    </collision>
  </link>
  <joint
    name="Joint_4"
    type="continuous">
    <origin
      xyz="-0.000799999999999756 -0.00258142672830974 -0.0789095822878361"
      rpy="0 0 0" />
    <parent
      link="Link_3" />
    <child
      link="Link_4" />
    <axis
      xyz="1 0 0" />
  </joint>
</robot>